2025-07-08 16:08:06,640 - INFO - Starting remote test execution...
2025-07-08 16:08:06,641 - INFO - Connecting to user@jtmksrv:656
2025-07-08 16:08:06,744 - INFO - Connected (version 2.0, client OpenSSH_7.6p1)
2025-07-08 16:08:06,922 - INFO - Authentication (password) successful!
2025-07-08 16:08:07,131 - INFO - [chan 0] Opened sftp connection (server version 3)
2025-07-08 16:08:07,132 - INFO - SSH connection established
2025-07-08 16:08:07,132 - INFO - Executing: mkdir -p \home\user\dataset\test_run
2025-07-08 16:08:07,264 - INFO - Uploading C:\Users\Intel\Desktop\InSDN_ddos_dataset\adversarial-ddos-attacks-sdn-dataset\dataset_generation\test_flow.py to \home\user\dataset\test_run\test_flow.py
2025-07-08 16:08:07,454 - INFO - Uploading C:\Users\Intel\Desktop\InSDN_ddos_dataset\adversarial-ddos-attacks-sdn-dataset\dataset_generation\test_config.json to \home\user\dataset\test_run\test_config.json
2025-07-08 16:08:07,537 - INFO - Executing: echo 1 | sudo -S pip install paramiko
2025-07-08 16:08:22,876 - INFO - Executing: echo 1 | sudo -S cd \home\user\dataset\test_run && python3 test_flow.py
2025-07-08 16:08:26,683 - INFO - Output: [sudo] password for user: sudo: cd: command not found
2025-07-08 16:08:26,765 - WARNING - Failed to download \home\user\dataset\test_run\test_traffic.pcap: [Errno 2] No such file
2025-07-08 16:08:26,786 - WARNING - Failed to download \home\user\dataset\test_run\test_features.csv: [Errno 2] No such file
2025-07-08 16:08:26,807 - WARNING - Failed to download \home\user\dataset\test_run\test_flow_features.csv: [Errno 2] No such file
2025-07-08 16:08:26,829 - WARNING - Failed to download \home\user\dataset\test_run\test_timeline.csv: [Errno 2] No such file
2025-07-08 16:08:26,854 - WARNING - Failed to download \home\user\dataset\test_run\test_flow.log: [Errno 2] No such file
2025-07-08 16:10:17,798 - INFO - Starting remote test execution...
2025-07-08 16:10:17,799 - INFO - Connecting to user@jtmksrv:656
2025-07-08 16:10:17,896 - INFO - Connected (version 2.0, client OpenSSH_7.6p1)
2025-07-08 16:10:18,042 - INFO - Authentication (password) successful!
2025-07-08 16:10:18,238 - INFO - [chan 0] Opened sftp connection (server version 3)
2025-07-08 16:10:18,239 - INFO - SSH connection established
2025-07-08 16:10:18,239 - INFO - Executing: mkdir -p \home\user\dataset\test_run
2025-07-08 16:10:18,372 - INFO - Uploading C:\Users\Intel\Desktop\InSDN_ddos_dataset\adversarial-ddos-attacks-sdn-dataset\dataset_generation\test_flow.py to \home\user\dataset\test_run\test_flow.py
2025-07-08 16:10:18,577 - INFO - Uploading C:\Users\Intel\Desktop\InSDN_ddos_dataset\adversarial-ddos-attacks-sdn-dataset\dataset_generation\test_config.json to \home\user\dataset\test_run\test_config.json
2025-07-08 16:10:18,727 - INFO - Executing: echo 1 | sudo -S pip install paramiko
2025-07-08 16:10:25,817 - INFO - Output: [sudo] password for user: /usr/lib/python3/dist-packages/secretstorage/dhcrypto.py:15: CryptographyDeprecationWarning: Python 3.6 is no longer supported by the Python core team. Therefore, support for it is deprecated in cryptography. The next release of cryptography will remove support for Python 3.6.
  from cryptography.utils import int_from_bytes
[33mWARNING: The directory '/home/user/.cache/pip' or its parent directory is not owned or is not writable by the current user. The cache has been disabled. Check the permissions and owner of that directory. If executing pip with sudo, you should use sudo's -H flag.[0m
Requirement already satisfied: paramiko in /usr/local/lib/python3.6/dist-packages (3.5.1)
Requirement already satisfied: bcrypt>=3.2 in /usr/local/lib/python3.6/dist-packages (from paramiko) (4.0.1)
Requirement already satisfied: cryptography>=3.3 in /usr/local/lib/python3.6/dist-packages (from paramiko) (40.0.2)
Requirement already satisfied: pynacl>=1.5 in /usr/local/lib/python3.6/dist-packages (from paramiko) (1.5.0)
Requirement already satisfied: cffi>=1.12 in /usr/local/lib/python3.6/dist-packages (from cryptography>=3.3->paramiko) (1.15.1)
Requirement already satisfied: pycparser in /usr/local/lib/python3.6/dist-packages (from cffi>=1.12->cryptography>=3.3->paramiko) (2.21)
[33mWARNING: Running pip as the 'root' user can result in broken permissions and conflicting behaviour with the system package manager. It is recommended to use a virtual environment instead: https://pip.pypa.io/warnings/venv[0m
2025-07-08 16:10:25,819 - INFO - Executing: echo 1 | sudo -S pip install mininet ryu scapy pandas
2025-07-08 16:10:54,972 - INFO - Executing: cd \home\user\dataset\test_run && sudo python3 test_flow.py
